<mujoco model="rm_65_b_description">
  <option iterations="50" timestep="0.001" integrator="implicitfast" gravity="0 0 -9.81" />

  <compiler angle="radian" meshdir="meshes" eulerseq="zyx" autolimits="true" />

  <default>
    <joint limited="true" damping="0.01" armature="0.01" frictionloss="0.01" />
    <geom condim="4" contype="1" conaffinity="15" friction="0.9 0.2 0.2" solref="0.001 2" />
    <equality solref="0.001 2" />
    <default class="visualgeom">
      <geom material="visualgeom" condim="1" contype="0" conaffinity="0" />
    </default>
  </default>

  <asset>
    <mesh name="base_link" file="base_link.STL" />
    <mesh name="link1" file="link1.STL" />
    <mesh name="link2" file="link2.STL" />
    <mesh name="link3" file="link3.STL" />
    <mesh name="link4" file="link4.STL" />
    <mesh name="link5" file="link5.STL" />
    <mesh name="link6" file="link6.STL" />
    <texture name="texplane" type="2d" builtin="checker" rgb1=".0 .0 .0" rgb2=".2 .2 .2" width="100" height="100" />
    <material name="matplane" reflectance="0." texture="texplane" texrepeat="1 1" texuniform="true" />
    <material name="visualgeom" rgba="0.5 0.9 0.2 1" />
  </asset>

  <worldbody>
    <light directional="true" diffuse="0.4 0.4 0.4" specular="0.1 0.1 0.1" pos="0 0 5.0" dir="0 0 -1" castshadow="false" />
    <light directional="true" diffuse="0.6 0.6 0.6" specular="0.2 0.2 0.2" pos="0 0 4" dir="0 0 -1" />
    <geom name="ground" type="plane" pos="0 0 0" size="100 100 0.001" quat="1 0 0 0" material="matplane" condim="3" conaffinity="15" />
    <camera name="fixed" pos="0 -3.0 0.5201641822241875" xyaxes="1 0 0 0 0 1" />
    <camera name="track" mode="trackcom" pos="0 -3.0 0.5201641822241875" xyaxes="1 0 0 0 0 1" />
    <body name="root" pos="0 0 0.020164182224187477" quat="1 0 0 0">
      <site name="imu" size="0.01" pos="0 0 0" />
      <geom type="mesh" rgba="1 1 1 1" mesh="base_link" contype="1" conaffinity="0" density="0" group="1" class="visualgeom" />
      <geom type="mesh" rgba="1 1 1 1" mesh="base_link" />
      <body name="Link1" pos="0 0 0.2405">
        <inertial pos="1.22263e-08 0.021108 -0.0251854" quat="0.988851 -0.148906 -2.80074e-05 -0.000243475" mass="0.593563" diaginertia="0.00126614 0.00124677 0.000496264" />
        <joint name="joint1" pos="0 0 0" axis="0 0 1" range="-3.1 3.1"/>
        <geom type="mesh" rgba="1 1 1 1" mesh="link1" contype="1" conaffinity="0" density="0" group="1" class="visualgeom" />
        <geom type="mesh" rgba="1 1 1 1" mesh="link1" />
        <body name="Link2" quat="0.499998 0.5 -0.5 0.500002">
          <inertial pos="0.152256 4.75384e-07 -0.0062026" quat="1.2834e-05 0.785787 1.90512e-05 0.618497" mass="0.864175" diaginertia="0.00735632 0.00733754 0.000513875" />
          <joint name="joint2" pos="0 0 0" axis="0 0 1" range="-2.268 2.268" actuatorfrcrange="-60 60" />
          <geom type="mesh" rgba="1 1 1 1" mesh="link2" contype="1" conaffinity="0" density="0" group="1" class="visualgeom" />
          <geom type="mesh" rgba="1 1 1 1" mesh="link2" />
          <body name="Link3" pos="0.256 0 0" quat="0.707105 0 0 0.707108">
            <inertial pos="5.05313e-06 -0.0595926 0.0105691" quat="0.424678 0.56496 -0.565554 0.424992" mass="0.289634" diaginertia="0.00065604 0.000637371 0.000114622" />
            <joint name="joint3" pos="0 0 0" axis="0 0 1" range="-2.355 2.355" actuatorfrcrange="-30 30" />
            <geom type="mesh" rgba="1 1 1 1" mesh="link3" contype="1" conaffinity="0" density="0" group="1" class="visualgeom" />
            <geom type="mesh" rgba="1 1 1 1" mesh="link3" />
            <body name="Link4" pos="0 -0.21 0" quat="0.707105 0.707108 0 0">
              <inertial pos="1.15517e-06 -0.0180424 -0.0215395" quat="0.990405 0.138195 -7.01319e-06 0.000110532" mass="0.23942" diaginertia="0.000285939 0.000275318 0.000107298" />
              <joint name="joint4" pos="0 0 0" axis="0 0 1" range="-3.1 3.1" actuatorfrcrange="-10 10" />
              <geom type="mesh" rgba="1 1 1 1" mesh="link4" contype="1" conaffinity="0" density="0" group="1" class="visualgeom" />
              <geom type="mesh" rgba="1 1 1 1" mesh="link4" />
              <body name="Link5" quat="0.707105 -0.707108 0 0">
                <inertial pos="3.19795e-06 -0.0593808 0.00736804" quat="0.419765 0.568659 -0.5692 0.420041" mass="0.2188" diaginertia="0.000358615 0.00035054 8.07958e-05" />
                <joint name="joint5" pos="0 0 0" axis="0 0 1" range="-2.233 2.233" actuatorfrcrange="-10 10" />
                <geom type="mesh" rgba="1 1 1 1" mesh="link5" contype="1" conaffinity="0" density="0" group="1" class="visualgeom" />
                <geom type="mesh" rgba="1 1 1 1" mesh="link5" />
                <body name="Link6" pos="0 -0.144 0" quat="0.707105 0.707108 0 0">
                  <inertial pos="0.000714235 -0.000396719 -0.0126724" quat="0.613063 0.350717 -0.614301 0.351831" mass="0.0649018" diaginertia="3.17886e-05 2.10548e-05 1.80205e-05" />
                  <joint name="joint6" pos="0 0 0" axis="0 0 1" range="-6.28 6.28" actuatorfrcrange="-10 10" />
                  <geom type="mesh" rgba="1 1 1 1" mesh="link6" contype="1" conaffinity="0" density="0" group="1" class="visualgeom" />
                  <geom type="mesh" rgba="1 1 1 1" mesh="link6" />
                </body>
              </body>
            </body>
          </body>
        </body>
      </body>
    </body>
    <site name="trace1" pos="0 0 0" size="0.01" rgba="1 0 0 1"/>
  </worldbody>
	<actuator>

    <general name="joint1" joint="joint1" gaintype="fixed" biastype="affine" gainprm="3000" biasprm="0 -3000 -300" ctrlrange="-2 2"/>

    <general name="joint2" joint="joint2" gaintype="fixed" biastype="affine" gainprm="1000" biasprm="0 -1000 -100" ctrlrange="-1.2 2.3"/>

   <general name="joint3" joint="joint3" gaintype="fixed" biastype="affine" gainprm="1000" biasprm="0 -1000 -100" ctrlrange="-1.2 2.3"/>

    <general name="joint4" joint="joint4" gaintype="fixed" biastype="affine" gainprm="1000" biasprm="0 -1000 -100" ctrlrange="-1.2 2.3"/>

    <general name="joint5" joint="joint5" gaintype="fixed" biastype="affine" gainprm="1000" biasprm="0 -1000 -100" ctrlrange="-1.2 2.3"/>

    <general name="joint6" joint="joint6" gaintype="fixed" biastype="affine" gainprm="1000" biasprm="0 -1000 -100" ctrlrange="-1.2 2.3"/>



	</actuator>


  <sensor>
    <actuatorpos name="joint1_p" actuator="joint1" />
    <actuatorvel name="joint1_v" actuator="joint1" />
    <actuatorfrc name="joint1_f" actuator="joint1" noise="0.001" />
    <actuatorpos name="joint2_p" actuator="joint2" />
    <actuatorvel name="joint2_v" actuator="joint2" />
    <actuatorfrc name="joint2_f" actuator="joint2" noise="0.001" />
    <actuatorpos name="joint3_p" actuator="joint3" />
    <actuatorvel name="joint3_v" actuator="joint3" />
    <actuatorfrc name="joint3_f" actuator="joint3" noise="0.001" />
    <actuatorpos name="joint4_p" actuator="joint4" />
    <actuatorvel name="joint4_v" actuator="joint4" />
    <actuatorfrc name="joint4_f" actuator="joint4" noise="0.001" />
    <actuatorpos name="joint5_p" actuator="joint5" />
    <actuatorvel name="joint5_v" actuator="joint5" />
    <actuatorfrc name="joint5_f" actuator="joint5" noise="0.001" />
    <actuatorpos name="joint6_p" actuator="joint6" />
    <actuatorvel name="joint6_v" actuator="joint6" />
    <actuatorfrc name="joint6_f" actuator="joint6" noise="0.001" />
    <framequat name="orientation" objtype="site" noise="0.001" objname="imu" />
    <gyro name="angular-velocity" site="imu" noise="0.005" cutoff="34.9" />
  </sensor>
</mujoco>
